Internal Server Error: /sec/rawData/
Traceback (most recent call last):
  File "/Library/Python/2.7/site-packages/django/core/handlers/base.py", line 149, in get_response
    response = self.process_exception_by_middleware(e, request)
  File "/Library/Python/2.7/site-packages/django/core/handlers/base.py", line 147, in get_response
    response = wrapped_callback(request, *callback_args, **callback_kwargs)
  File "/Library/Python/2.7/site-packages/django/views/generic/base.py", line 68, in view
    return self.dispatch(request, *args, **kwargs)
  File "/Library/Python/2.7/site-packages/django/views/generic/base.py", line 88, in dispatch
    return handler(request, *args, **kwargs)
  File "/Users/yazhu/PycharmProjects/valueAnalysis/valueCrawler/views.py", line 14, in get
    getAllCompanies()
  File "/Users/yazhu/PycharmProjects/valueAnalysis/valueCrawler/crawlFunction/companies.py", line 17, in getAllCompanies
    data = json.load(urlopen_with_retry("http://sec.kimonolabs.com/companies?apikey=iv2stYAlaKITqEJ1CN4fwpSLHSZyF6EH&offset=" + str(offset)))
  File "/System/Library/Frameworks/Python.framework/Versions/2.7/lib/python2.7/json/__init__.py", line 286, in load
    return loads(fp.read(),
  File "/System/Library/Frameworks/Python.framework/Versions/2.7/lib/python2.7/socket.py", line 355, in read
    data = self._sock.recv(rbufsize)
  File "/System/Library/Frameworks/Python.framework/Versions/2.7/lib/python2.7/httplib.py", line 612, in read
    s = self.fp.read(amt)
  File "/System/Library/Frameworks/Python.framework/Versions/2.7/lib/python2.7/socket.py", line 384, in read
    data = self._sock.recv(left)
timeout: timed out
Internal Server Error: /sec/rawData/
Traceback (most recent call last):
  File "/Library/Python/2.7/site-packages/django/core/handlers/base.py", line 149, in get_response
    response = self.process_exception_by_middleware(e, request)
  File "/Library/Python/2.7/site-packages/django/core/handlers/base.py", line 147, in get_response
    response = wrapped_callback(request, *callback_args, **callback_kwargs)
  File "/Library/Python/2.7/site-packages/django/views/generic/base.py", line 68, in view
    return self.dispatch(request, *args, **kwargs)
  File "/Library/Python/2.7/site-packages/django/views/generic/base.py", line 88, in dispatch
    return handler(request, *args, **kwargs)
  File "/Users/yazhu/PycharmProjects/valueAnalysis/valueCrawler/views.py", line 14, in get
    getAllCompanies()
  File "/Users/yazhu/PycharmProjects/valueAnalysis/valueCrawler/crawlFunction/companies.py", line 22, in getAllCompanies
    data = json.load(response)
  File "/System/Library/Frameworks/Python.framework/Versions/2.7/lib/python2.7/json/__init__.py", line 286, in load
    return loads(fp.read(),
  File "/System/Library/Frameworks/Python.framework/Versions/2.7/lib/python2.7/socket.py", line 355, in read
    data = self._sock.recv(rbufsize)
  File "/System/Library/Frameworks/Python.framework/Versions/2.7/lib/python2.7/httplib.py", line 612, in read
    s = self.fp.read(amt)
  File "/System/Library/Frameworks/Python.framework/Versions/2.7/lib/python2.7/socket.py", line 384, in read
    data = self._sock.recv(left)
timeout: timed out
Internal Server Error: /sec/rawData/
Traceback (most recent call last):
  File "/Library/Python/2.7/site-packages/django/core/handlers/base.py", line 149, in get_response
    response = self.process_exception_by_middleware(e, request)
  File "/Library/Python/2.7/site-packages/django/core/handlers/base.py", line 147, in get_response
    response = wrapped_callback(request, *callback_args, **callback_kwargs)
  File "/Library/Python/2.7/site-packages/django/views/generic/base.py", line 68, in view
    return self.dispatch(request, *args, **kwargs)
  File "/Library/Python/2.7/site-packages/django/views/generic/base.py", line 88, in dispatch
    return handler(request, *args, **kwargs)
  File "/Users/yazhu/PycharmProjects/valueAnalysis/valueCrawler/views.py", line 14, in get
    getAllCompanies()
  File "/Users/yazhu/PycharmProjects/valueAnalysis/valueCrawler/crawlFunction/companies.py", line 22, in getAllCompanies
    data = json.load(response)
  File "/System/Library/Frameworks/Python.framework/Versions/2.7/lib/python2.7/json/__init__.py", line 286, in load
    return loads(fp.read(),
  File "/System/Library/Frameworks/Python.framework/Versions/2.7/lib/python2.7/socket.py", line 355, in read
    data = self._sock.recv(rbufsize)
  File "/System/Library/Frameworks/Python.framework/Versions/2.7/lib/python2.7/httplib.py", line 612, in read
    s = self.fp.read(amt)
  File "/System/Library/Frameworks/Python.framework/Versions/2.7/lib/python2.7/socket.py", line 384, in read
    data = self._sock.recv(left)
timeout: timed out
Internal Server Error: /sec/rawData/
Traceback (most recent call last):
  File "/Library/Python/2.7/site-packages/django/core/handlers/base.py", line 149, in get_response
    response = self.process_exception_by_middleware(e, request)
  File "/Library/Python/2.7/site-packages/django/core/handlers/base.py", line 147, in get_response
    response = wrapped_callback(request, *callback_args, **callback_kwargs)
  File "/Library/Python/2.7/site-packages/django/views/generic/base.py", line 68, in view
    return self.dispatch(request, *args, **kwargs)
  File "/Library/Python/2.7/site-packages/django/views/generic/base.py", line 88, in dispatch
    return handler(request, *args, **kwargs)
  File "/Users/yazhu/PycharmProjects/valueAnalysis/valueCrawler/views.py", line 14, in get
    getAllCompanies()
  File "/Users/yazhu/PycharmProjects/valueAnalysis/valueCrawler/crawlFunction/companies.py", line 182, in getAllCompanies
    company.save()
  File "/Library/Python/2.7/site-packages/django/db/models/base.py", line 700, in save
    force_update=force_update, update_fields=update_fields)
  File "/Library/Python/2.7/site-packages/django/db/models/base.py", line 728, in save_base
    updated = self._save_table(raw, cls, force_insert, force_update, using, update_fields)
  File "/Library/Python/2.7/site-packages/django/db/models/base.py", line 812, in _save_table
    result = self._do_insert(cls._base_manager, using, fields, update_pk, raw)
  File "/Library/Python/2.7/site-packages/django/db/models/base.py", line 851, in _do_insert
    using=using, raw=raw)
  File "/Library/Python/2.7/site-packages/django/db/models/manager.py", line 122, in manager_method
    return getattr(self.get_queryset(), name)(*args, **kwargs)
  File "/Library/Python/2.7/site-packages/django/db/models/query.py", line 1039, in _insert
    return query.get_compiler(using=using).execute_sql(return_id)
  File "/Library/Python/2.7/site-packages/django/db/models/sql/compiler.py", line 1064, in execute_sql
    cursor.execute(sql, params)
  File "/Library/Python/2.7/site-packages/django/db/backends/utils.py", line 79, in execute
    return super(CursorDebugWrapper, self).execute(sql, params)
  File "/Library/Python/2.7/site-packages/django/db/backends/utils.py", line 64, in execute
    return self.cursor.execute(sql, params)
  File "/Library/Python/2.7/site-packages/django/db/utils.py", line 95, in __exit__
    six.reraise(dj_exc_type, dj_exc_value, traceback)
  File "/Library/Python/2.7/site-packages/django/db/backends/utils.py", line 64, in execute
    return self.cursor.execute(sql, params)
  File "/Library/Python/2.7/site-packages/django/db/backends/sqlite3/base.py", line 323, in execute
    return Database.Cursor.execute(self, query, params)
OperationalError: no such table: valueCrawler_company
Internal Server Error: /sec/rawData/
Traceback (most recent call last):
  File "/Library/Python/2.7/site-packages/django/core/handlers/base.py", line 149, in get_response
    response = self.process_exception_by_middleware(e, request)
  File "/Library/Python/2.7/site-packages/django/core/handlers/base.py", line 147, in get_response
    response = wrapped_callback(request, *callback_args, **callback_kwargs)
  File "/Library/Python/2.7/site-packages/django/views/generic/base.py", line 68, in view
    return self.dispatch(request, *args, **kwargs)
  File "/Library/Python/2.7/site-packages/django/views/generic/base.py", line 88, in dispatch
    return handler(request, *args, **kwargs)
  File "/Users/yazhu/PycharmProjects/valueAnalysis/valueCrawler/views.py", line 14, in get
    getAllCompanies()
  File "/Users/yazhu/PycharmProjects/valueAnalysis/valueCrawler/crawlFunction/companies.py", line 182, in getAllCompanies
    company.save()
  File "/Library/Python/2.7/site-packages/django/db/models/base.py", line 700, in save
    force_update=force_update, update_fields=update_fields)
  File "/Library/Python/2.7/site-packages/django/db/models/base.py", line 728, in save_base
    updated = self._save_table(raw, cls, force_insert, force_update, using, update_fields)
  File "/Library/Python/2.7/site-packages/django/db/models/base.py", line 812, in _save_table
    result = self._do_insert(cls._base_manager, using, fields, update_pk, raw)
  File "/Library/Python/2.7/site-packages/django/db/models/base.py", line 851, in _do_insert
    using=using, raw=raw)
  File "/Library/Python/2.7/site-packages/django/db/models/manager.py", line 122, in manager_method
    return getattr(self.get_queryset(), name)(*args, **kwargs)
  File "/Library/Python/2.7/site-packages/django/db/models/query.py", line 1039, in _insert
    return query.get_compiler(using=using).execute_sql(return_id)
  File "/Library/Python/2.7/site-packages/django/db/models/sql/compiler.py", line 1064, in execute_sql
    cursor.execute(sql, params)
  File "/Library/Python/2.7/site-packages/django/db/backends/utils.py", line 79, in execute
    return super(CursorDebugWrapper, self).execute(sql, params)
  File "/Library/Python/2.7/site-packages/django/db/backends/utils.py", line 64, in execute
    return self.cursor.execute(sql, params)
  File "/Library/Python/2.7/site-packages/django/db/utils.py", line 95, in __exit__
    six.reraise(dj_exc_type, dj_exc_value, traceback)
  File "/Library/Python/2.7/site-packages/django/db/backends/utils.py", line 64, in execute
    return self.cursor.execute(sql, params)
  File "/Library/Python/2.7/site-packages/django/db/backends/sqlite3/base.py", line 323, in execute
    return Database.Cursor.execute(self, query, params)
OperationalError: table valueCrawler_company has no column named entityId
Internal Server Error: /sec/rawData/
Traceback (most recent call last):
  File "/Library/Python/2.7/site-packages/django/core/handlers/base.py", line 149, in get_response
    response = self.process_exception_by_middleware(e, request)
  File "/Library/Python/2.7/site-packages/django/core/handlers/base.py", line 147, in get_response
    response = wrapped_callback(request, *callback_args, **callback_kwargs)
  File "/Library/Python/2.7/site-packages/django/views/generic/base.py", line 68, in view
    return self.dispatch(request, *args, **kwargs)
  File "/Library/Python/2.7/site-packages/django/views/generic/base.py", line 88, in dispatch
    return handler(request, *args, **kwargs)
  File "/Users/yazhu/PycharmProjects/valueAnalysis/valueCrawler/views.py", line 14, in get
    getAllCompanies()
  File "/Users/yazhu/PycharmProjects/valueAnalysis/valueCrawler/crawlFunction/companies.py", line 182, in getAllCompanies
    company.save()
  File "/Library/Python/2.7/site-packages/django/db/models/base.py", line 700, in save
    force_update=force_update, update_fields=update_fields)
  File "/Library/Python/2.7/site-packages/django/db/models/base.py", line 728, in save_base
    updated = self._save_table(raw, cls, force_insert, force_update, using, update_fields)
  File "/Library/Python/2.7/site-packages/django/db/models/base.py", line 812, in _save_table
    result = self._do_insert(cls._base_manager, using, fields, update_pk, raw)
  File "/Library/Python/2.7/site-packages/django/db/models/base.py", line 851, in _do_insert
    using=using, raw=raw)
  File "/Library/Python/2.7/site-packages/django/db/models/manager.py", line 122, in manager_method
    return getattr(self.get_queryset(), name)(*args, **kwargs)
  File "/Library/Python/2.7/site-packages/django/db/models/query.py", line 1039, in _insert
    return query.get_compiler(using=using).execute_sql(return_id)
  File "/Library/Python/2.7/site-packages/django/db/models/sql/compiler.py", line 1064, in execute_sql
    cursor.execute(sql, params)
  File "/Library/Python/2.7/site-packages/django/db/backends/utils.py", line 79, in execute
    return super(CursorDebugWrapper, self).execute(sql, params)
  File "/Library/Python/2.7/site-packages/django/db/backends/utils.py", line 64, in execute
    return self.cursor.execute(sql, params)
  File "/Library/Python/2.7/site-packages/django/db/utils.py", line 95, in __exit__
    six.reraise(dj_exc_type, dj_exc_value, traceback)
  File "/Library/Python/2.7/site-packages/django/db/backends/utils.py", line 64, in execute
    return self.cursor.execute(sql, params)
  File "/Library/Python/2.7/site-packages/django/db/backends/sqlite3/base.py", line 323, in execute
    return Database.Cursor.execute(self, query, params)
OperationalError: table valueCrawler_company has no column named entityId
Internal Server Error: /sec/rawData/
Traceback (most recent call last):
  File "/Library/Python/2.7/site-packages/django/core/handlers/base.py", line 149, in get_response
    response = self.process_exception_by_middleware(e, request)
  File "/Library/Python/2.7/site-packages/django/core/handlers/base.py", line 147, in get_response
    response = wrapped_callback(request, *callback_args, **callback_kwargs)
  File "/Library/Python/2.7/site-packages/django/views/generic/base.py", line 68, in view
    return self.dispatch(request, *args, **kwargs)
  File "/Library/Python/2.7/site-packages/django/views/generic/base.py", line 88, in dispatch
    return handler(request, *args, **kwargs)
  File "/Users/yazhu/PycharmProjects/valueAnalysis/valueCrawler/views.py", line 14, in get
    getAllCompanies()
  File "/Users/yazhu/PycharmProjects/valueAnalysis/valueCrawler/crawlFunction/companies.py", line 73, in getAllCompanies
    secForm.cashEquivalentsAndShortTermInvestments = companyForm['cashequivalentsandshortterminvestments']
KeyError: 'cashequivalentsandshortterminvestments'
Internal Server Error: /sec/rawData/
Traceback (most recent call last):
  File "/Library/Python/2.7/site-packages/django/core/handlers/base.py", line 149, in get_response
    response = self.process_exception_by_middleware(e, request)
  File "/Library/Python/2.7/site-packages/django/core/handlers/base.py", line 147, in get_response
    response = wrapped_callback(request, *callback_args, **callback_kwargs)
  File "/Library/Python/2.7/site-packages/django/views/generic/base.py", line 68, in view
    return self.dispatch(request, *args, **kwargs)
  File "/Library/Python/2.7/site-packages/django/views/generic/base.py", line 88, in dispatch
    return handler(request, *args, **kwargs)
  File "/Users/yazhu/PycharmProjects/valueAnalysis/valueCrawler/views.py", line 14, in get
    getAllCompanies()
  File "/Users/yazhu/PycharmProjects/valueAnalysis/valueCrawler/crawlFunction/companies.py", line 95, in getAllCompanies
    secForm.save()
  File "/Library/Python/2.7/site-packages/django/db/models/base.py", line 700, in save
    force_update=force_update, update_fields=update_fields)
  File "/Library/Python/2.7/site-packages/django/db/models/base.py", line 728, in save_base
    updated = self._save_table(raw, cls, force_insert, force_update, using, update_fields)
  File "/Library/Python/2.7/site-packages/django/db/models/base.py", line 812, in _save_table
    result = self._do_insert(cls._base_manager, using, fields, update_pk, raw)
  File "/Library/Python/2.7/site-packages/django/db/models/base.py", line 851, in _do_insert
    using=using, raw=raw)
  File "/Library/Python/2.7/site-packages/django/db/models/manager.py", line 122, in manager_method
    return getattr(self.get_queryset(), name)(*args, **kwargs)
  File "/Library/Python/2.7/site-packages/django/db/models/query.py", line 1039, in _insert
    return query.get_compiler(using=using).execute_sql(return_id)
  File "/Library/Python/2.7/site-packages/django/db/models/sql/compiler.py", line 1063, in execute_sql
    for sql, params in self.as_sql():
  File "/Library/Python/2.7/site-packages/django/db/models/sql/compiler.py", line 1023, in as_sql
    for obj in self.query.objs
  File "/Library/Python/2.7/site-packages/django/db/models/sql/compiler.py", line 962, in prepare_value
    value = field.get_db_prep_save(value, connection=self.connection)
  File "/Library/Python/2.7/site-packages/django/db/models/fields/__init__.py", line 728, in get_db_prep_save
    prepared=False)
  File "/Library/Python/2.7/site-packages/django/db/models/fields/__init__.py", line 1301, in get_db_prep_value
    value = self.get_prep_value(value)
  File "/Library/Python/2.7/site-packages/django/db/models/fields/__init__.py", line 1296, in get_prep_value
    return self.to_python(value)
  File "/Library/Python/2.7/site-packages/django/db/models/fields/__init__.py", line 1273, in to_python
    params={'value': value},
ValidationError: [u"'12/31/2014' value has an invalid date format. It must be in YYYY-MM-DD format."]
Internal Server Error: /sec/rawData/
Traceback (most recent call last):
  File "/Library/Python/2.7/site-packages/django/core/handlers/base.py", line 149, in get_response
    response = self.process_exception_by_middleware(e, request)
  File "/Library/Python/2.7/site-packages/django/core/handlers/base.py", line 147, in get_response
    response = wrapped_callback(request, *callback_args, **callback_kwargs)
  File "/Library/Python/2.7/site-packages/django/views/generic/base.py", line 68, in view
    return self.dispatch(request, *args, **kwargs)
  File "/Library/Python/2.7/site-packages/django/views/generic/base.py", line 88, in dispatch
    return handler(request, *args, **kwargs)
  File "/Users/yazhu/PycharmProjects/valueAnalysis/valueCrawler/views.py", line 14, in get
    getAllCompanies()
  File "/Users/yazhu/PycharmProjects/valueAnalysis/valueCrawler/crawlFunction/companies.py", line 48, in getAllCompanies
    secForm.periodEndDate = datetime.datetime.strptime(companyForm['periodenddate'], "%Y/%m/%d")
  File "/System/Library/Frameworks/Python.framework/Versions/2.7/lib/python2.7/_strptime.py", line 325, in _strptime
    (data_string, format))
ValueError: time data '12/31/2014' does not match format '%Y/%m/%d'
Internal Server Error: /sec/rawData/
Traceback (most recent call last):
  File "/Library/Python/2.7/site-packages/django/core/handlers/base.py", line 149, in get_response
    response = self.process_exception_by_middleware(e, request)
  File "/Library/Python/2.7/site-packages/django/core/handlers/base.py", line 147, in get_response
    response = wrapped_callback(request, *callback_args, **callback_kwargs)
  File "/Library/Python/2.7/site-packages/django/views/generic/base.py", line 68, in view
    return self.dispatch(request, *args, **kwargs)
  File "/Library/Python/2.7/site-packages/django/views/generic/base.py", line 88, in dispatch
    return handler(request, *args, **kwargs)
  File "/Users/yazhu/PycharmProjects/valueAnalysis/valueCrawler/views.py", line 14, in get
    getAllCompanies()
  File "/Users/yazhu/PycharmProjects/valueAnalysis/valueCrawler/crawlFunction/companies.py", line 168, in getAllCompanies
    'treasurystock ' + companyForm['treasurystock'] + '; ')
TypeError: coercing to Unicode: need string or buffer, int found
Internal Server Error: /sec/rawData/
Traceback (most recent call last):
  File "/Library/Python/2.7/site-packages/django/core/handlers/base.py", line 149, in get_response
    response = self.process_exception_by_middleware(e, request)
  File "/Library/Python/2.7/site-packages/django/core/handlers/base.py", line 147, in get_response
    response = wrapped_callback(request, *callback_args, **callback_kwargs)
  File "/Library/Python/2.7/site-packages/django/views/generic/base.py", line 68, in view
    return self.dispatch(request, *args, **kwargs)
  File "/Library/Python/2.7/site-packages/django/views/generic/base.py", line 88, in dispatch
    return handler(request, *args, **kwargs)
  File "/Users/yazhu/PycharmProjects/valueAnalysis/valueCrawler/views.py", line 14, in get
    getAllCompanies()
  File "/Users/yazhu/PycharmProjects/valueAnalysis/valueCrawler/crawlFunction/companies.py", line 95, in getAllCompanies
    secForm.save()
  File "/Library/Python/2.7/site-packages/django/db/models/base.py", line 700, in save
    force_update=force_update, update_fields=update_fields)
  File "/Library/Python/2.7/site-packages/django/db/models/base.py", line 728, in save_base
    updated = self._save_table(raw, cls, force_insert, force_update, using, update_fields)
  File "/Library/Python/2.7/site-packages/django/db/models/base.py", line 812, in _save_table
    result = self._do_insert(cls._base_manager, using, fields, update_pk, raw)
  File "/Library/Python/2.7/site-packages/django/db/models/base.py", line 851, in _do_insert
    using=using, raw=raw)
  File "/Library/Python/2.7/site-packages/django/db/models/manager.py", line 122, in manager_method
    return getattr(self.get_queryset(), name)(*args, **kwargs)
  File "/Library/Python/2.7/site-packages/django/db/models/query.py", line 1039, in _insert
    return query.get_compiler(using=using).execute_sql(return_id)
  File "/Library/Python/2.7/site-packages/django/db/models/sql/compiler.py", line 1064, in execute_sql
    cursor.execute(sql, params)
  File "/Library/Python/2.7/site-packages/django/db/backends/utils.py", line 79, in execute
    return super(CursorDebugWrapper, self).execute(sql, params)
  File "/Library/Python/2.7/site-packages/django/db/backends/utils.py", line 64, in execute
    return self.cursor.execute(sql, params)
  File "/Library/Python/2.7/site-packages/django/db/utils.py", line 95, in __exit__
    six.reraise(dj_exc_type, dj_exc_value, traceback)
  File "/Library/Python/2.7/site-packages/django/db/backends/utils.py", line 64, in execute
    return self.cursor.execute(sql, params)
  File "/Library/Python/2.7/site-packages/django/db/backends/sqlite3/base.py", line 323, in execute
    return Database.Cursor.execute(self, query, params)
IntegrityError: NOT NULL constraint failed: valueCrawler_secform.changeInInventories
Internal Server Error: /sec/rawData/
Traceback (most recent call last):
  File "/Library/Python/2.7/site-packages/django/core/handlers/base.py", line 149, in get_response
    response = self.process_exception_by_middleware(e, request)
  File "/Library/Python/2.7/site-packages/django/core/handlers/base.py", line 147, in get_response
    response = wrapped_callback(request, *callback_args, **callback_kwargs)
  File "/Library/Python/2.7/site-packages/django/views/generic/base.py", line 68, in view
    return self.dispatch(request, *args, **kwargs)
  File "/Library/Python/2.7/site-packages/django/views/generic/base.py", line 88, in dispatch
    return handler(request, *args, **kwargs)
  File "/Users/yazhu/PycharmProjects/valueAnalysis/valueCrawler/views.py", line 14, in get
    getAllCompanies()
  File "/Users/yazhu/PycharmProjects/valueAnalysis/valueCrawler/crawlFunction/companies.py", line 95, in getAllCompanies
    secForm.save()
  File "/Library/Python/2.7/site-packages/django/db/models/base.py", line 700, in save
    force_update=force_update, update_fields=update_fields)
  File "/Library/Python/2.7/site-packages/django/db/models/base.py", line 728, in save_base
    updated = self._save_table(raw, cls, force_insert, force_update, using, update_fields)
  File "/Library/Python/2.7/site-packages/django/db/models/base.py", line 812, in _save_table
    result = self._do_insert(cls._base_manager, using, fields, update_pk, raw)
  File "/Library/Python/2.7/site-packages/django/db/models/base.py", line 851, in _do_insert
    using=using, raw=raw)
  File "/Library/Python/2.7/site-packages/django/db/models/manager.py", line 122, in manager_method
    return getattr(self.get_queryset(), name)(*args, **kwargs)
  File "/Library/Python/2.7/site-packages/django/db/models/query.py", line 1039, in _insert
    return query.get_compiler(using=using).execute_sql(return_id)
  File "/Library/Python/2.7/site-packages/django/db/models/sql/compiler.py", line 1064, in execute_sql
    cursor.execute(sql, params)
  File "/Library/Python/2.7/site-packages/django/db/backends/utils.py", line 79, in execute
    return super(CursorDebugWrapper, self).execute(sql, params)
  File "/Library/Python/2.7/site-packages/django/db/backends/utils.py", line 64, in execute
    return self.cursor.execute(sql, params)
  File "/Library/Python/2.7/site-packages/django/db/utils.py", line 95, in __exit__
    six.reraise(dj_exc_type, dj_exc_value, traceback)
  File "/Library/Python/2.7/site-packages/django/db/backends/utils.py", line 64, in execute
    return self.cursor.execute(sql, params)
  File "/Library/Python/2.7/site-packages/django/db/backends/sqlite3/base.py", line 323, in execute
    return Database.Cursor.execute(self, query, params)
IntegrityError: NOT NULL constraint failed: valueCrawler_secform.period
Not Found: /
Not Found: /sec/rawData
Internal Server Error: /sec/rawData/
Traceback (most recent call last):
  File "/Library/Python/2.7/site-packages/django/core/handlers/base.py", line 149, in get_response
    response = self.process_exception_by_middleware(e, request)
  File "/Library/Python/2.7/site-packages/django/core/handlers/base.py", line 147, in get_response
    response = wrapped_callback(request, *callback_args, **callback_kwargs)
  File "/Library/Python/2.7/site-packages/django/views/generic/base.py", line 68, in view
    return self.dispatch(request, *args, **kwargs)
  File "/Library/Python/2.7/site-packages/django/views/generic/base.py", line 88, in dispatch
    return handler(request, *args, **kwargs)
  File "/Users/yazhu/PycharmProjects/valueAnalysis/valueCrawler/views.py", line 14, in get
    getAllCompanies()
  File "/Users/yazhu/PycharmProjects/valueAnalysis/valueCrawler/crawlFunction/companies.py", line 168, in getAllCompanies
    'treasurystock ' + companyForm['treasurystock'] + '; ')
TypeError: coercing to Unicode: need string or buffer, int found
Internal Server Error: /sec/rawData/
Traceback (most recent call last):
  File "/Library/Python/2.7/site-packages/django/core/handlers/base.py", line 149, in get_response
    response = self.process_exception_by_middleware(e, request)
  File "/Library/Python/2.7/site-packages/django/core/handlers/base.py", line 147, in get_response
    response = wrapped_callback(request, *callback_args, **callback_kwargs)
  File "/Library/Python/2.7/site-packages/django/views/generic/base.py", line 68, in view
    return self.dispatch(request, *args, **kwargs)
  File "/Library/Python/2.7/site-packages/django/views/generic/base.py", line 88, in dispatch
    return handler(request, *args, **kwargs)
  File "/Users/yazhu/PycharmProjects/valueAnalysis/valueCrawler/views.py", line 14, in get
    getAllCompanies()
  File "/Users/yazhu/PycharmProjects/valueAnalysis/valueCrawler/crawlFunction/companies.py", line 168, in getAllCompanies
    'treasurystock ' + str(companyForm['treasurystock']) + '; ')
TypeError: coercing to Unicode: need string or buffer, int found
Internal Server Error: /sec/rawData/
Traceback (most recent call last):
  File "/Library/Python/2.7/site-packages/django/core/handlers/base.py", line 149, in get_response
    response = self.process_exception_by_middleware(e, request)
  File "/Library/Python/2.7/site-packages/django/core/handlers/base.py", line 147, in get_response
    response = wrapped_callback(request, *callback_args, **callback_kwargs)
  File "/Library/Python/2.7/site-packages/django/views/generic/base.py", line 68, in view
    return self.dispatch(request, *args, **kwargs)
  File "/Library/Python/2.7/site-packages/django/views/generic/base.py", line 88, in dispatch
    return handler(request, *args, **kwargs)
  File "/Users/yazhu/PycharmProjects/valueAnalysis/valueCrawler/views.py", line 14, in get
    getAllCompanies()
  File "/Users/yazhu/PycharmProjects/valueAnalysis/valueCrawler/crawlFunction/companies.py", line 168, in getAllCompanies
    'treasurystock ' + str(companyForm['treasurystock']) + '; ')
TypeError: coercing to Unicode: need string or buffer, int found
Internal Server Error: /sec/rawData/
Traceback (most recent call last):
  File "/Library/Python/2.7/site-packages/django/core/handlers/base.py", line 149, in get_response
    response = self.process_exception_by_middleware(e, request)
  File "/Library/Python/2.7/site-packages/django/core/handlers/base.py", line 147, in get_response
    response = wrapped_callback(request, *callback_args, **callback_kwargs)
  File "/Library/Python/2.7/site-packages/django/views/generic/base.py", line 68, in view
    return self.dispatch(request, *args, **kwargs)
  File "/Library/Python/2.7/site-packages/django/views/generic/base.py", line 88, in dispatch
    return handler(request, *args, **kwargs)
  File "/Users/yazhu/PycharmProjects/valueAnalysis/valueCrawler/views.py", line 14, in get
    getAllCompanies()
  File "/Users/yazhu/PycharmProjects/valueAnalysis/valueCrawler/crawlFunction/companies.py", line 98, in getAllCompanies
    fileHanlde3.write(field + ' ' + str(companyForm[field]) + ', ')
ValueError: I/O operation on closed file
Internal Server Error: /sec/rawData/
Traceback (most recent call last):
  File "/Library/Python/2.7/site-packages/django/core/handlers/base.py", line 149, in get_response
    response = self.process_exception_by_middleware(e, request)
  File "/Library/Python/2.7/site-packages/django/core/handlers/base.py", line 147, in get_response
    response = wrapped_callback(request, *callback_args, **callback_kwargs)
  File "/Library/Python/2.7/site-packages/django/views/generic/base.py", line 68, in view
    return self.dispatch(request, *args, **kwargs)
  File "/Library/Python/2.7/site-packages/django/views/generic/base.py", line 88, in dispatch
    return handler(request, *args, **kwargs)
  File "/Users/yazhu/PycharmProjects/valueAnalysis/valueCrawler/views.py", line 14, in get
    getAllCompanies()
  File "/Users/yazhu/PycharmProjects/valueAnalysis/valueCrawler/crawlFunction/companies.py", line 95, in getAllCompanies
    secForm.save()
  File "/Library/Python/2.7/site-packages/django/db/models/base.py", line 651, in save
    "unsaved related object '%s'." % field.name
ValueError: save() prohibited to prevent data loss due to unsaved related object 'company'.
Internal Server Error: /sec/rawData/
Traceback (most recent call last):
  File "/Library/Python/2.7/site-packages/django/core/handlers/base.py", line 149, in get_response
    response = self.process_exception_by_middleware(e, request)
  File "/Library/Python/2.7/site-packages/django/core/handlers/base.py", line 147, in get_response
    response = wrapped_callback(request, *callback_args, **callback_kwargs)
  File "/Library/Python/2.7/site-packages/django/views/generic/base.py", line 68, in view
    return self.dispatch(request, *args, **kwargs)
  File "/Library/Python/2.7/site-packages/django/views/generic/base.py", line 88, in dispatch
    return handler(request, *args, **kwargs)
  File "/Users/yazhu/PycharmProjects/valueAnalysis/valueCrawler/views.py", line 14, in get
    getAllCompanies()
  File "/Users/yazhu/PycharmProjects/valueAnalysis/valueCrawler/crawlFunction/companies.py", line 33, in getAllCompanies
    company.sicCode = int(sec['sic_code'])
TypeError: int() argument must be a string or a number, not 'NoneType'
Not Found: /sec/rawData/
Not Found: /sec/rawData/a
Not Found: /sec/rawData/a
Internal Server Error: /sec/graph/a/
Traceback (most recent call last):
  File "/Library/Python/2.7/site-packages/django/core/handlers/base.py", line 149, in get_response
    response = self.process_exception_by_middleware(e, request)
  File "/Library/Python/2.7/site-packages/django/core/handlers/base.py", line 147, in get_response
    response = wrapped_callback(request, *callback_args, **callback_kwargs)
  File "/Library/Python/2.7/site-packages/django/views/generic/base.py", line 68, in view
    return self.dispatch(request, *args, **kwargs)
  File "/Library/Python/2.7/site-packages/django/views/generic/base.py", line 88, in dispatch
    return handler(request, *args, **kwargs)
  File "/Users/yazhu/PycharmProjects/valueAnalysis/valueCrawler/views.py", line 16, in get
    company = Company.objects.get(symbol=kwargs['symbol'])
  File "/Library/Python/2.7/site-packages/django/db/models/manager.py", line 122, in manager_method
    return getattr(self.get_queryset(), name)(*args, **kwargs)
  File "/Library/Python/2.7/site-packages/django/db/models/query.py", line 387, in get
    self.model._meta.object_name
DoesNotExist: Company matching query does not exist.
Not Found: /sec/graph/aapl
Internal Server Error: /sec/graph/aapl/
Traceback (most recent call last):
  File "/Library/Python/2.7/site-packages/django/core/handlers/base.py", line 149, in get_response
    response = self.process_exception_by_middleware(e, request)
  File "/Library/Python/2.7/site-packages/django/core/handlers/base.py", line 147, in get_response
    response = wrapped_callback(request, *callback_args, **callback_kwargs)
  File "/Library/Python/2.7/site-packages/django/views/generic/base.py", line 68, in view
    return self.dispatch(request, *args, **kwargs)
  File "/Library/Python/2.7/site-packages/django/views/generic/base.py", line 88, in dispatch
    return handler(request, *args, **kwargs)
  File "/Users/yazhu/PycharmProjects/valueAnalysis/valueCrawler/views.py", line 16, in get
    company = Company.objects.get(symbol=kwargs['symbol'])
  File "/Library/Python/2.7/site-packages/django/db/models/manager.py", line 122, in manager_method
    return getattr(self.get_queryset(), name)(*args, **kwargs)
  File "/Library/Python/2.7/site-packages/django/db/models/query.py", line 387, in get
    self.model._meta.object_name
DoesNotExist: Company matching query does not exist.
Internal Server Error: /sec/graph/lnkd/
Traceback (most recent call last):
  File "/Library/Python/2.7/site-packages/django/core/handlers/base.py", line 149, in get_response
    response = self.process_exception_by_middleware(e, request)
  File "/Library/Python/2.7/site-packages/django/core/handlers/base.py", line 147, in get_response
    response = wrapped_callback(request, *callback_args, **callback_kwargs)
  File "/Library/Python/2.7/site-packages/django/views/generic/base.py", line 68, in view
    return self.dispatch(request, *args, **kwargs)
  File "/Library/Python/2.7/site-packages/django/views/generic/base.py", line 88, in dispatch
    return handler(request, *args, **kwargs)
  File "/Users/yazhu/PycharmProjects/valueAnalysis/valueCrawler/views.py", line 16, in get
    company = Company.objects.get(symbol=kwargs['symbol'])
  File "/Library/Python/2.7/site-packages/django/db/models/manager.py", line 122, in manager_method
    return getattr(self.get_queryset(), name)(*args, **kwargs)
  File "/Library/Python/2.7/site-packages/django/db/models/query.py", line 387, in get
    self.model._meta.object_name
DoesNotExist: Company matching query does not exist.
Not Found: /sec/graph/lnkd/
Not Found: /sec/graph/AAPL/
Internal Server Error: /sec/graph/ZYRX/
Traceback (most recent call last):
  File "/Library/Python/2.7/site-packages/django/core/handlers/base.py", line 149, in get_response
    response = self.process_exception_by_middleware(e, request)
  File "/Library/Python/2.7/site-packages/django/core/handlers/base.py", line 147, in get_response
    response = wrapped_callback(request, *callback_args, **callback_kwargs)
  File "/Library/Python/2.7/site-packages/django/views/generic/base.py", line 68, in view
    return self.dispatch(request, *args, **kwargs)
  File "/Library/Python/2.7/site-packages/django/views/generic/base.py", line 88, in dispatch
    return handler(request, *args, **kwargs)
  File "/Users/yazhu/PycharmProjects/valueAnalysis/valueCrawler/views.py", line 18, in get
    response.context_data['companyNum'] = len(Company.objects.all())
  File "/Library/Python/2.7/site-packages/django/db/models/query.py", line 240, in __len__
    self._fetch_all()
  File "/Library/Python/2.7/site-packages/django/db/models/query.py", line 1074, in _fetch_all
    self._result_cache = list(self.iterator())
  File "/Library/Python/2.7/site-packages/django/db/models/query.py", line 52, in __iter__
    results = compiler.execute_sql()
  File "/Library/Python/2.7/site-packages/django/db/models/sql/compiler.py", line 852, in execute_sql
    cursor.execute(sql, params)
  File "/Library/Python/2.7/site-packages/django/db/backends/utils.py", line 79, in execute
    return super(CursorDebugWrapper, self).execute(sql, params)
  File "/Library/Python/2.7/site-packages/django/db/backends/utils.py", line 64, in execute
    return self.cursor.execute(sql, params)
  File "/Library/Python/2.7/site-packages/django/db/utils.py", line 95, in __exit__
    six.reraise(dj_exc_type, dj_exc_value, traceback)
  File "/Library/Python/2.7/site-packages/django/db/backends/utils.py", line 64, in execute
    return self.cursor.execute(sql, params)
  File "/Library/Python/2.7/site-packages/django/db/backends/sqlite3/base.py", line 323, in execute
    return Database.Cursor.execute(self, query, params)
OperationalError: no such table: valueCrawler_company
Internal Server Error: /sec/graph/ZYRX/
Traceback (most recent call last):
  File "/Library/Python/2.7/site-packages/django/core/handlers/base.py", line 149, in get_response
    response = self.process_exception_by_middleware(e, request)
  File "/Library/Python/2.7/site-packages/django/core/handlers/base.py", line 147, in get_response
    response = wrapped_callback(request, *callback_args, **callback_kwargs)
  File "/Library/Python/2.7/site-packages/django/views/generic/base.py", line 68, in view
    return self.dispatch(request, *args, **kwargs)
  File "/Library/Python/2.7/site-packages/django/views/generic/base.py", line 88, in dispatch
    return handler(request, *args, **kwargs)
  File "/Users/yazhu/PycharmProjects/valueAnalysis/valueCrawler/views.py", line 18, in get
    response.context_data['companyNum'] = len(Company.objects.all())
  File "/Library/Python/2.7/site-packages/django/db/models/query.py", line 240, in __len__
    self._fetch_all()
  File "/Library/Python/2.7/site-packages/django/db/models/query.py", line 1074, in _fetch_all
    self._result_cache = list(self.iterator())
  File "/Library/Python/2.7/site-packages/django/db/models/query.py", line 52, in __iter__
    results = compiler.execute_sql()
  File "/Library/Python/2.7/site-packages/django/db/models/sql/compiler.py", line 852, in execute_sql
    cursor.execute(sql, params)
  File "/Library/Python/2.7/site-packages/django/db/backends/utils.py", line 79, in execute
    return super(CursorDebugWrapper, self).execute(sql, params)
  File "/Library/Python/2.7/site-packages/django/db/backends/utils.py", line 64, in execute
    return self.cursor.execute(sql, params)
  File "/Library/Python/2.7/site-packages/django/db/utils.py", line 95, in __exit__
    six.reraise(dj_exc_type, dj_exc_value, traceback)
  File "/Library/Python/2.7/site-packages/django/db/backends/utils.py", line 64, in execute
    return self.cursor.execute(sql, params)
  File "/Library/Python/2.7/site-packages/django/db/backends/sqlite3/base.py", line 323, in execute
    return Database.Cursor.execute(self, query, params)
OperationalError: no such table: valueCrawler_company
Not Found: /sec/graph/ZYRX/
Not Found: /sec/graph/ZYRX/
Not Found: /sec/graph/ZYRX/
Not Found: /
Not Found: /favicon.ico
Not Found: /sec/graph/aapl/
Internal Server Error: /sec/graph/AAPL/forms
Traceback (most recent call last):
  File "/Library/Python/2.7/site-packages/django/core/handlers/base.py", line 132, in get_response
    response = wrapped_callback(request, *callback_args, **callback_kwargs)
  File "/Library/Python/2.7/site-packages/django/views/generic/base.py", line 71, in view
    return self.dispatch(request, *args, **kwargs)
  File "/Library/Python/2.7/site-packages/django/views/generic/base.py", line 89, in dispatch
    return handler(request, *args, **kwargs)
  File "/Users/yazhu/workspace/companymatrix/valueCrawler/views.py", line 39, in get
    response = super(GetSymbolGraph, self).get(request, *args, **kwargs)
TypeError: super(type, obj): obj must be an instance or subtype of type
Internal Server Error: /sec/graph/AAPL/forms
Traceback (most recent call last):
  File "/Library/Python/2.7/site-packages/django/core/handlers/base.py", line 132, in get_response
    response = wrapped_callback(request, *callback_args, **callback_kwargs)
  File "/Library/Python/2.7/site-packages/django/views/generic/base.py", line 71, in view
    return self.dispatch(request, *args, **kwargs)
  File "/Library/Python/2.7/site-packages/django/views/generic/base.py", line 89, in dispatch
    return handler(request, *args, **kwargs)
  File "/Users/yazhu/workspace/companymatrix/valueCrawler/views.py", line 43, in get
    forms = get_list_or_404(SecForm, company=company)
  File "/Library/Python/2.7/site-packages/django/shortcuts.py", line 169, in get_list_or_404
    obj_list = list(queryset.filter(*args, **kwargs))
  File "/Library/Python/2.7/site-packages/django/db/models/query.py", line 679, in filter
    return self._filter_or_exclude(False, *args, **kwargs)
  File "/Library/Python/2.7/site-packages/django/db/models/query.py", line 697, in _filter_or_exclude
    clone.query.add_q(Q(*args, **kwargs))
  File "/Library/Python/2.7/site-packages/django/db/models/sql/query.py", line 1309, in add_q
    clause, require_inner = self._add_q(where_part, self.used_aliases)
  File "/Library/Python/2.7/site-packages/django/db/models/sql/query.py", line 1337, in _add_q
    allow_joins=allow_joins, split_subq=split_subq,
  File "/Library/Python/2.7/site-packages/django/db/models/sql/query.py", line 1199, in build_filter
    lookups, value)
  File "/Library/Python/2.7/site-packages/django/db/models/fields/related.py", line 1751, in get_lookup_constraint
    lookup_class(target.get_col(alias, source), val), AND)
  File "/Library/Python/2.7/site-packages/django/db/models/lookups.py", line 101, in __init__
    self.rhs = self.get_prep_lookup()
  File "/Library/Python/2.7/site-packages/django/db/models/lookups.py", line 139, in get_prep_lookup
    return self.lhs.output_field.get_prep_lookup(self.lookup_name, self.rhs)
  File "/Library/Python/2.7/site-packages/django/db/models/fields/__init__.py", line 727, in get_prep_lookup
    return self.get_prep_value(value)
  File "/Library/Python/2.7/site-packages/django/db/models/fields/__init__.py", line 985, in get_prep_value
    return int(value)
TypeError: int() argument must be a string or a number, not 'list'
Not Found: /sec/graph/AAPL
Not Found: /
Not Found: /favicon.ico
Not Found: /twitterApi/
Internal Server Error: /tweetSentiment/twitterApi/
Traceback (most recent call last):
  File "/Library/Python/2.7/site-packages/django/core/handlers/base.py", line 132, in get_response
    response = wrapped_callback(request, *callback_args, **callback_kwargs)
  File "/Library/Python/2.7/site-packages/django/views/generic/base.py", line 71, in view
    return self.dispatch(request, *args, **kwargs)
  File "/Library/Python/2.7/site-packages/django/views/generic/base.py", line 89, in dispatch
    return handler(request, *args, **kwargs)
  File "/Users/yazhu/workspace/companymatrix/tweetSentiment/views/views.py", line 15, in get
    response.content['test'] = test
  File "/Library/Python/2.7/site-packages/django/template/response.py", line 178, in content
    raise ContentNotRenderedError('The response content must be '
ContentNotRenderedError: The response content must be rendered before it can be accessed.
Internal Server Error: /tweetSentiment/twitterApi/
Traceback (most recent call last):
  File "/Library/Python/2.7/site-packages/django/core/handlers/base.py", line 132, in get_response
    response = wrapped_callback(request, *callback_args, **callback_kwargs)
  File "/Library/Python/2.7/site-packages/django/views/generic/base.py", line 71, in view
    return self.dispatch(request, *args, **kwargs)
  File "/Library/Python/2.7/site-packages/django/views/generic/base.py", line 89, in dispatch
    return handler(request, *args, **kwargs)
  File "/Users/yazhu/workspace/companymatrix/tweetSentiment/views/views.py", line 15, in get
    response.content['test'] = test
  File "/Library/Python/2.7/site-packages/django/template/response.py", line 178, in content
    raise ContentNotRenderedError('The response content must be '
ContentNotRenderedError: The response content must be rendered before it can be accessed.
Internal Server Error: /tweetSentiment/twitterApi/
Traceback (most recent call last):
  File "/Library/Python/2.7/site-packages/django/core/handlers/base.py", line 132, in get_response
    response = wrapped_callback(request, *callback_args, **callback_kwargs)
  File "/Library/Python/2.7/site-packages/django/views/generic/base.py", line 71, in view
    return self.dispatch(request, *args, **kwargs)
  File "/Library/Python/2.7/site-packages/django/views/generic/base.py", line 89, in dispatch
    return handler(request, *args, **kwargs)
  File "/Users/yazhu/workspace/companymatrix/tweetSentiment/views/views.py", line 16, in get
    response.content['test'] = json.dumps(test, ensure_ascii=False)
  File "/Library/Python/2.7/site-packages/django/template/response.py", line 178, in content
    raise ContentNotRenderedError('The response content must be '
ContentNotRenderedError: The response content must be rendered before it can be accessed.
Internal Server Error: /tweetSentiment/twitterApi/
Traceback (most recent call last):
  File "/Library/Python/2.7/site-packages/django/core/handlers/base.py", line 132, in get_response
    response = wrapped_callback(request, *callback_args, **callback_kwargs)
  File "/Library/Python/2.7/site-packages/django/views/generic/base.py", line 71, in view
    return self.dispatch(request, *args, **kwargs)
  File "/Library/Python/2.7/site-packages/django/views/generic/base.py", line 89, in dispatch
    return handler(request, *args, **kwargs)
  File "/Users/yazhu/workspace/companymatrix/tweetSentiment/views/views.py", line 16, in get
    response.content['test'] = 'haha'
  File "/Library/Python/2.7/site-packages/django/template/response.py", line 178, in content
    raise ContentNotRenderedError('The response content must be '
ContentNotRenderedError: The response content must be rendered before it can be accessed.
